Workbook

Sheet Asignacion
C2: OPERACION - Coopmorteros | N2: 2026
Y3: OPERACIÓN COOPMORTEROS - Hace referencia a la cantidad del tiempo que el personal de IT esta disponible para soportar y mantener las unidades de negocio que ya se encuentran operativas y facturando.
G4: =$E$24*H23 -> 3779248.4 | I4: =$E$24*J23 -> 2205742.3 | K4: =$E$24*L23 -> 2932054.4 | M4: =$E$24*N23 -> 1203584.7 | O4: =$E$24*P23 -> 165813.61 | Q4: =$E$24*R23 -> 0 | S4: =$E$24*T23 -> 0 | U4: =$E$24*V23 -> 165813.61
D5: Costo Laboral % | E5: Horas asignadas | F5: Asignado $$ operación | G5: Adm. | I5: Energia | K5: Agua | M5: Tele. | O5: Canal 50 | Q5: CAC | S5: Alm. Taller. | U5: Serv. Sociales
G6: Hs. Asignadas | H6: Impacto $$ | I6: Hs. Asignadas | J6: Impacto $$ | K6: Hs. Asignadas | L6: Impacto $$ | M6: Hs. Asignadas | N6: Impacto $$ | O6: Hs. Asignadas | P6: Impacto $$ | Q6: Hs. Asignadas | R6: Impacto $$ | S6: Hs. Asignadas | T6: Impacto $$ | U6: Hs. Asignadas | V6: Impacto $$
Y7: Semana 1 - 05 al 11 | Z7: Semana 2 - 12 al 18 | AA7: Semana 3 -19 al 25 | AB7: Semana 4 - 26 al 31
B8: Enero 2026 | C8: Leonardo Depetris | D8: 0.1913 | E8: 0.55 | F8: 0.105215 | G8: 0.15 | H8: 0.028695 | I8: 0 | J8: 0 | K8: 0.4 | L8: 0.07652 | M8: 0 | N8: 0 | O8: 0 | P8: 0 | Q8: 0 | R8: 0 | S8: 0 | T8: 0 | U8: 0 | V8: 0 | Y8: Gestiones Cooptech / Accionamiento bombeo de crudo / Viaje Marcos Juarez / Diseño +Agua | Z8: Presupuesto y presentación Marcos Juarez / Indicadores y variables calculadas +Agua / Reparación en cisterna de ósmosis | AA8: Informe triple impacto / Testing control de bombas / Chapas Santa Rosa | AB8: VACACIONES
C9: Claudio Bottero | D9: 0.1299 | E9: 0.5 | F9: 0.06495 | G9: 0.2 | H9: 0.02598 | I9: 0 | J9: 0 | K9: 0 | L9: 0 | M9: 0.2 | N9: 0.02598 | O9: 0.05 | P9: 0.006495 | Q9: 0 | R9: 0 | S9: 0 | T9: 0 | U9: 0.05 | V9: 0.006495 | Y9: Trabajos varios datacenter / Cloudflare Unquillo / DB reloj fichero / reclamo ADIT / rack sepelio | Z9: MKT Castelli / HLS Bingo 9 / Actualización K8S / Ajustes tacural | AA9: MKT Santa Rosa Starlink / Actualiz. MQTT / Migración VMS proxmox / DB O.V. (Emi. Marangoni) | AB9: Act. Unquillo / VM nueva MQTT / reunión B1Tech / server facturas Porteña
C10: Carola Clausen | D10: 0.1231 | E10: 0 | F10: 0 | G10: 0 | H10: 0 | I10: 0 | J10: 0 | K10: 0 | L10: 0 | M10: 0 | N10: 0 | O10: 0 | P10: 0 | Q10: 0 | R10: 0 | S10: 0 | T10: 0 | U10: 0 | V10: 0 | Y10: VACACIONES | Z10: VACACIONES | AA10: VACACIONES | AB10: Ventas Cooptech
C11: Lorenzo Depetris | D11: 0.1328 | E11: 0.4 | F11: 0.05312 | G11: 0 | H11: 0 | I11: 0.3 | J11: 0.03984 | K11: 0.1 | L11: 0.01328 | M11: 0 | N11: 0 | O11: 0 | P11: 0 | Q11: 0 | R11: 0 | S11: 0 | T11: 0 | U11: 0 | V11: 0 | Y11: Sensor ultrasónico / Soporte remoto Ucacha | Z11: Sensor ultrasónico / Soporte remoto Ucacha / Problema reconectadores | AA11: Soporte remoto Ucacha / Lector de pulsos / Problema reconectadores | AB11: Problema reconectadores / Viaje Santa Rosa
C12: Juan Gonzalez | D12: 0.1411 | E12: 0.25 | F12: 0.035275 | G12: 0 | H12: 0 | I12: 0.1 | J12: 0.01411 | K12: 0 | L12: 0 | M12: 0.15 | N12: 0.021165 | O12: 0 | P12: 0 | Q12: 0 | R12: 0 | S12: 0 | T12: 0 | U12: 0 | V12: 0 | Y12: VACACIONES | Z12: Reconecta Desktop | AA12: Actualizaciones Provision / Alarmas Deadmen | AB12: Alarmas Deadmen / Configuración K8S
C13: Julieta Costamagna | D13: 0.1167 | E13: 0.8 | F13: 0.09336 | G13: 0.8 | H13: 0.09336 | I13: 0 | J13: 0 | K13: 0 | L13: 0 | M13: 0 | N13: 0 | O13: 0 | P13: 0 | Q13: 0 | R13: 0 | S13: 0 | T13: 0 | U13: 0 | V13: 0 | Y13: O.V. Pña / Web Unquillo /Módulo recupero de materiales | Z13: Módulo recupero de materiales / Módulo facturas proveedores | AA13: Módulo factura proveedores / acueducto | AB13: Módulo factura proveedores / acueducto / recupero de materiales
C14: Agustin Aressi | D14: 0.1002 | E14: 0.25 | F14: 0.02505 | G14: 0 | H14: 0 | I14: 0 | J14: 0 | K14: 0.25 | L14: 0.02505 | M14: 0 | N14: 0 | O14: 0 | P14: 0 | Q14: 0 | R14: 0 | S14: 0 | T14: 0 | U14: 0 | V14: 0 | Y14: Nuevas funcionalidades +Agua: optimización de gráficos | Z14: Nuevas funcionalidades +Agua: órdebenes bombeo | AA14: Nuevas funcionalidades +Agua: múltiple led /modificación microservicios | AB14: Nuevas funcionalidades +Agua: Rio 3°
C15: Matías Gandino | D15: 0.0649 | E15: 0.5 | F15: 0.03245 | G15: 0 | H15: 0 | I15: 0.5 | J15: 0.03245 | K15: 0 | L15: 0 | M15: 0 | N15: 0 | O15: 0 | P15: 0 | Q15: 0 | R15: 0 | S15: 0 | T15: 0 | U15: 0 | V15: 0 | Y15: Sensores ultrasónicos / Analizadores de red | Z15: Analizadores de red / Implementación Santa Rosa | AA15: Analizadores de red | AB15: Analizadores de red / Implementación Santa Rosa
C16: xxx | D16: 0 | E16: 0 | F16: 0 | G16: 0 | H16: 0 | I16: 0 | J16: 0 | K16: 0 | L16: 0 | M16: 0 | N16: 0 | O16: 0 | P16: 0 | Q16: 0 | R16: 0 | S16: 0 | T16: 0 | U16: 0 | V16: 0
C17: xxx | D17: 0 | E17: 0 | F17: 0 | G17: 0 | H17: 0 | I17: 0 | J17: 0 | K17: 0 | L17: 0 | M17: 0 | N17: 0 | O17: 0 | P17: 0 | Q17: 0 | R17: 0 | S17: 0 | T17: 0 | U17: 0 | V17: 0
C18: xxx | D18: 0 | E18: 0 | F18: 0 | G18: 0 | H18: 0 | I18: 0 | J18: 0 | K18: 0 | L18: 0 | M18: 0 | N18: 0 | O18: 0 | P18: 0 | Q18: 0 | R18: 0 | S18: 0 | T18: 0 | U18: 0 | V18: 0
C19: xxx | D19: 0 | E19: 0 | F19: 0 | G19: 0 | H19: 0 | I19: 0 | J19: 0 | K19: 0 | L19: 0 | M19: 0 | N19: 0 | O19: 0 | P19: 0 | Q19: 0 | R19: 0 | S19: 0 | T19: 0 | U19: 0 | V19: 0
C20: xxx | D20: 0 | E20: 0 | F20: 0 | G20: 0 | H20: 0 | I20: 0 | J20: 0 | K20: 0 | L20: 0 | M20: 0 | N20: 0 | O20: 0 | P20: 0 | Q20: 0 | R20: 0 | S20: 0 | T20: 0 | U20: 0 | V20: 0
C21: xxx | D21: 0 | E21: 0 | F21: 0 | G21: 0 | H21: 0 | I21: 0 | J21: 0 | K21: 0 | L21: 0 | M21: 0 | N21: 0 | O21: 0 | P21: 0 | Q21: 0 | R21: 0 | S21: 0 | T21: 0 | U21: 0 | V21: 0
C22: xxx | D22: 0 | E22: 0 | F22: 0 | G22: 0 | H22: 0 | I22: 0 | J22: 0 | K22: 0 | L22: 0 | M22: 0 | N22: 0 | O22: 0 | P22: 0 | Q22: 0 | R22: 0 | S22: 0 | T22: 0 | U22: 0 | V22: 0
E23: =SUM(E8:E22) -> 3.25 | H23: =SUM(H8:H22) -> 0.148035 | J23: =SUM(J8:J22) -> 0.0864 | L23: =SUM(L8:L22) -> 0.11485 | N23: =SUM(N8:N22) -> 0.047145 | P23: =SUM(P8:P22) -> 0.006495 | R23: =SUM(R8:R22) -> 0 | T23: =SUM(T8:T22) -> 0 | V23: =SUM(V8:V22) -> 0.006495
B24: Costo laboral Enero | E24: 25529425
K25: Cotizacion dólar | N25: 1465 | O25: 46053
B26: ASIGNACION TOTAL HORAS OPERACION | F26: =SUM(E8:E22)/8 -> 0.40625
B27: ASIGNACION TOTAL $$$ OPERACION | F27: =SUM(F8:F22) -> 0.40942 | I27: =E24*F27 -> 10452257 | M27: =I27/N25 -> 7134.6465
B29: ASIGNACION TOTAL HORAS COOPTECH | F29: =1-F26 -> 0.59375
B30: ASIGNACION TOTAL $$$ COOPTECH | F30: =1-F27 -> 0.59058 | I30: =E24*F30 -> 15077168 | M30: =I30/N25 -> 10291.582
B32: HORAS I+D A ACTIVAR | F32: =(8-(E23-E8-E11))/8 -> 0.7125 | I32: =I30*F32 -> 10742482 | M32: =M30*F32 -> 7332.7522 | P32: LAS HORAS A ACTIVAR SON UN PORCENTAJE DE LAS HORAS DESIGNADAS A PROYECTOS DE COOPTECH
B33: HORAS ASIGNADAS A GASTO | I33: =I30-I32 -> 4334685.7 | M33: =M30-M32 -> 2958.8298
Y34: OPERACIÓN COOPMORTEROS - Hace referencia a la cantidad del tiempo que el personal de IT esta disponible para soportar y mantener las unidades de negocio que ya se encuentran operativas y facturando.
G35: =$E$54*H53 -> 3992455.1 | I35: =$E$54*J53 -> 2390239.2 | K35: =$E$54*L53 -> 850018.3 | M35: =$E$54*N53 -> 2438939.6 | O35: =$E$54*P53 -> 0 | Q35: =$E$54*R53 -> 0 | S35: =$E$54*T53 -> 164853.73 | U35: =$E$54*V53 -> 0
D36: Costo Laboral % | E36: Horas asignadas | F36: Asignado $$ operación | G36: Adm. | I36: Energia | K36: Agua | M36: Tele. | O36: Canal 50 | Q36: CAC | S36: Alm. Taller. | U36: Serv. Sociales
G37: Hs. Asignadas | H37: Impacto $$ | I37: Hs. Asignadas | J37: Impacto $$ | K37: Hs. Asignadas | L37: Impacto $$ | M37: Hs. Asignadas | N37: Impacto $$ | O37: Hs. Asignadas | P37: Impacto $$ | Q37: Hs. Asignadas | R37: Impacto $$ | S37: Hs. Asignadas | T37: Impacto $$ | U37: Hs. Asignadas | V37: Impacto $$
Y38: Semana 1 - 03 al 07 | Z38: Semana 2 - 10 al 14 | AA38: Semana 3 - 17 al 21 | AB38: Semana 4 - 24 al 28
B39: Febrero 2026 | C39: Leonardo Depetris | D39: 0.2035 | E39: 0.6 | F39: 0.1221 | G39: 0.3 | H39: 0.06105 | I39: 0.2 | J39: 0.0407 | K39: 0.1 | L39: 0.02035 | M39: 0 | N39: 0 | O39: 0 | P39: 0 | Q39: 0 | R39: 0 | S39: 0 | T39: 0 | U39: 0 | V39: 0 | Y39: Medidores de energía Itron / Tabla Reconecta / Reparación IdP recuperadas Cooper | Z39: Armado Kits clientes Cooptech / Charla-Taller Cooptech / Evaluaciones de desempeño | AA39: Metodología KanBan / demo +Agua | AB39: Reunionces comerciales / Implementación Ucacha / Mejoras bombeo agua cruda
C40: Claudio Bottero | D40: 0.1503 | E40: 0.4 | F40: 0.06012 | G40: 0.2 | H40: 0.03006 | I40: 0 | J40: 0 | K40: 0 | L40: 0 | M40: 0.2 | N40: 0.03006 | O40: 0 | P40: 0 | Q40: 0 | R40: 0 | S40: 0 | T40: 0 | U40: 0 | V40: 0 | Y40: Server facturas porteña / nodos k8s / mqtt energia / viaje miramar | Z40: Actualizaciones varias / clientes coopcloud | AA40: Actualizaciones server MQTT | AB40: Limpieza VMs PMX / Implementación Ucacha / Agente Procoop / Rancher / VMs mutual
C41: Carola Clausen | D41: 0.1016 | E41: 0 | F41: 0 | G41: 0 | H41: 0 | I41: 0 | J41: 0 | K41: 0 | L41: 0 | M41: 0 | N41: 0 | O41: 0 | P41: 0 | Q41: 0 | R41: 0 | S41: 0 | T41: 0 | U41: 0 | V41: 0 | Y41: Ventas cooptech | Z41: Ventas cooptech | AA41: Ventas cooptech | AB41: Ventas cooptech
C42: Lorenzo Depetris | D42: 0.149 | E42: 0.3 | F42: 0.0447 | G42: 0 | H42: 0 | I42: 0.3 | J42: 0.0447 | K42: 0 | L42: 0 | M42: 0 | N42: 0 | O42: 0 | P42: 0 | Q42: 0 | R42: 0 | S42: 0 | T42: 0 | U42: 0 | V42: 0 | Y42: Ticket maniobra reconectadores | Z42: Viaje Santa Rosa / Armado Kits clientes Cooptech / Charla-Taller Cooptech / Actualización devoto | AA42: Accesorio Relé / Revision reco Marconi | AB42: Implementación Ucacha
C43: Juan Gonzalez | D43: 0.1427 | E43: 0.4 | F43: 0.05708 | G43: 0 | H43: 0 | I43: 0 | J43: 0 | K43: 0 | L43: 0 | M43: 0.4 | N43: 0.05708 | O43: 0 | P43: 0 | Q43: 0 | R43: 0 | S43: 0 | T43: 0 | U43: 0 | V43: 0 | Y43: Coopate / Alarmas deadmen / Provision | Z43: Provision / Charla-Taller Cooptech / Reconecta | AA43: Reconecta | AB43: Provision: plan empresa
...

Sheet asientos
A2: 46023
A3: Activacion de Hs | B3: =+Asignacion!I32 -> 10742482
A4: Venta Interna Energia | B4: =+Asignacion!I4 -> 2205742.3
A5: Venta Interna Agua | B5: =+Asignacion!K4 -> 2932054.4
A6: Venta Interna Telecomunicaciones | B6: =+Asignacion!M4 -> 1203584.7
A7: Venta Interna Canal 50 | B7: =+Asignacion!O4 -> 165813.61
A8: Venta Interna Administracion | B8: =+Asignacion!G4 -> 3779248.4
A9: Venta Interna Serv. Sociales | B9: =+Asignacion!U4 -> 165813.61
A11: 46054
A12: Activacion de Hs | B12: =+Asignacion!I62 -> 13954537
A13: Venta Interna Energia | B13: =+Asignacion!I35 -> 2390239.2
A14: Venta Interna Agua | B14: =+Asignacion!K35 -> 850018.3
A15: Venta Interna Telecomunicaciones | B15: =+Asignacion!M35 -> 2438939.6
A16: Venta Interna Canal 50 | B16: =+Asignacion!O13 -> 0
A17: Venta Interna Administracion | B17: =+Asignacion!G35+Asignacion!S35 -> 4157308.8
A18: Venta Interna Serv. Sociales | B18: =+Asignacion!U13 -> 0
A20: 46082
A21: Activacion de Hs | B21: =+Asignacion!I92 -> 10632782
A22: Venta Interna Energia | B22: =+Asignacion!I65 -> 342945.53
A23: Venta Interna Agua | B23: =+Asignacion!K65 -> 1235205.2
A24: Venta Interna Telecomunicaciones | B24: =+Asignacion!M65 -> 4894536
A25: Venta Interna Canal 50 | B25: =+Asignacion!O22 -> 0
A26: Venta Interna Administracion | B26: =+Asignacion!G65+Asignacion!S65 -> 6395454.2
A27: Venta Interna Serv. Sociales | B27: =+Asignacion!U22 -> 0
A29: 46113
A30: Activacion de Hs | B30: =+Asignacion!I122 -> 6522888.6
A31: Venta Interna Energia | B31: =+Asignacion!I95 -> 993605.65
A32: Venta Interna Agua | B32: =+Asignacion!K95 -> 2162553.5
A33: Venta Interna Telecomunicaciones | B33: =+Asignacion!M95 -> 3109888.3
A34: Venta Interna Canal 50 | B34: =+Asignacion!O95 -> 297107.57
A35: Venta Interna Administracion | B35: =+Asignacion!G95+Asignacion!Q95 -> 5418560.2
A36: Venta Interna Serv. Sociales | B36: =+Asignacion!U31 -> 0
A39: 46143
A40: Activacion de Hs | B40: =+Asignacion!I152 -> 7629316.5
A41: Venta Interna Energia | B41: =+Asignacion!I125 -> 4109248.3
A42: Venta Interna Agua | B42: =+Asignacion!K125 -> 1446895
A43: Venta Interna Telecomunicaciones | B43: =+Asignacion!M125 -> 646856.96
A44: Venta Interna Canal 50 | B44: =+Asignacion!O125 -> 384062.65
A45: Venta Interna Administracion | B45: =+Asignacion!G125 -> 8137466.1
A46: Venta Interna Serv. Sociales | B46: =+Asignacion!U41 -> 0
